<?xml version="1.0" encoding="utf-8"?>
<!-- =================================================================================== -->
<!-- |    This document was autogenerated by xacro from snake_stl.xacro                | -->
<!-- |    EDITING THIS FILE BY HAND IS NOT RECOMMENDED                                 | -->
<!-- =================================================================================== -->
<robot name="test_robot">
  <link name="world"/>
  <!-- マクロ関数の定義 -->
  <!-- link名 -->
  <link name="dynamixel_001">
    <!-- 見た目 -->
    <visual>
      <geometry>
        <mesh filename="package://snake/mesh/dynamixel.stl"/>
      </geometry>
      <material name="red">
        <color rgba="0.7 0.0 0.0 1.0"/>
      </material>
      <origin rpy="0 0 0" xyz="0 0 0"/>
    </visual>
    <!--物理的特性-->
    <!--干渉-->
    <collision>
      <geometry>
        <mesh filename="package://snake/mesh/dynamixel.stl"/>
      </geometry>
    </collision>
    <!--慣性-->
    <inertial>
      <mass value="0.023967239474"/>
      <inertia ixx="3.5392036062e-06" ixy="0" ixz="0" iyy="3.2067700889e-06" iyz="0" izz="2.5171567719e-06"/>
    </inertial>
  </link>
  <!-- link名 -->
  <link name="dynamixel_101">
    <!-- 見た目 -->
    <visual>
      <geometry>
        <mesh filename="package://snake/mesh/dynamixel.stl"/>
      </geometry>
      <material name="red">
        <color rgba="0.7 0.0 0.0 1.0"/>
      </material>
      <origin rpy="0 0 0" xyz="0 0 0"/>
    </visual>
    <!--物理的特性-->
    <!--干渉-->
    <collision>
      <geometry>
        <mesh filename="package://snake/mesh/dynamixel.stl"/>
      </geometry>
    </collision>
    <!--慣性-->
    <inertial>
      <mass value="0.023967239474"/>
      <inertia ixx="3.5392036062e-06" ixy="0" ixz="0" iyy="3.2067700889e-06" iyz="0" izz="2.5171567719e-06"/>
    </inertial>
  </link>
  <!-- link名 -->
  <link name="dynamixel_002">
    <!-- 見た目 -->
    <visual>
      <geometry>
        <mesh filename="package://snake/mesh/dynamixel.stl"/>
      </geometry>
      <material name="red">
        <color rgba="0.7 0.0 0.0 1.0"/>
      </material>
      <origin rpy="0 0 0" xyz="0 0 0"/>
    </visual>
    <!--物理的特性-->
    <!--干渉-->
    <collision>
      <geometry>
        <mesh filename="package://snake/mesh/dynamixel.stl"/>
      </geometry>
    </collision>
    <!--慣性-->
    <inertial>
      <mass value="0.023967239474"/>
      <inertia ixx="3.5392036062e-06" ixy="0" ixz="0" iyy="3.2067700889e-06" iyz="0" izz="2.5171567719e-06"/>
    </inertial>
  </link>
  <!-- link名 -->
  <link name="dynamixel_102">
    <!-- 見た目 -->
    <visual>
      <geometry>
        <mesh filename="package://snake/mesh/dynamixel.stl"/>
      </geometry>
      <material name="red">
        <color rgba="0.7 0.0 0.0 1.0"/>
      </material>
      <origin rpy="0 0 0" xyz="0 0 0"/>
    </visual>
    <!--物理的特性-->
    <!--干渉-->
    <collision>
      <geometry>
        <mesh filename="package://snake/mesh/dynamixel.stl"/>
      </geometry>
    </collision>
    <!--慣性-->
    <inertial>
      <mass value="0.023967239474"/>
      <inertia ixx="3.5392036062e-06" ixy="0" ixz="0" iyy="3.2067700889e-06" iyz="0" izz="2.5171567719e-06"/>
    </inertial>
  </link>
  <!-- link名 -->
  <link name="dynamixel_003">
    <!-- 見た目 -->
    <visual>
      <geometry>
        <mesh filename="package://snake/mesh/dynamixel.stl"/>
      </geometry>
      <material name="red">
        <color rgba="0.7 0.0 0.0 1.0"/>
      </material>
      <origin rpy="0 0 0" xyz="0 0 0"/>
    </visual>
    <!--物理的特性-->
    <!--干渉-->
    <collision>
      <geometry>
        <mesh filename="package://snake/mesh/dynamixel.stl"/>
      </geometry>
    </collision>
    <!--慣性-->
    <inertial>
      <mass value="0.023967239474"/>
      <inertia ixx="3.5392036062e-06" ixy="0" ixz="0" iyy="3.2067700889e-06" iyz="0" izz="2.5171567719e-06"/>
    </inertial>
  </link>
  <!-- link名 -->
  <link name="dynamixel_103">
    <!-- 見た目 -->
    <visual>
      <geometry>
        <mesh filename="package://snake/mesh/dynamixel.stl"/>
      </geometry>
      <material name="red">
        <color rgba="0.7 0.0 0.0 1.0"/>
      </material>
      <origin rpy="0 0 0" xyz="0 0 0"/>
    </visual>
    <!--物理的特性-->
    <!--干渉-->
    <collision>
      <geometry>
        <mesh filename="package://snake/mesh/dynamixel.stl"/>
      </geometry>
    </collision>
    <!--慣性-->
    <inertial>
      <mass value="0.023967239474"/>
      <inertia ixx="3.5392036062e-06" ixy="0" ixz="0" iyy="3.2067700889e-06" iyz="0" izz="2.5171567719e-06"/>
    </inertial>
  </link>
  <!-- link名 -->
  <link name="dynamixel_004">
    <!-- 見た目 -->
    <visual>
      <geometry>
        <mesh filename="package://snake/mesh/dynamixel.stl"/>
      </geometry>
      <material name="red">
        <color rgba="0.7 0.0 0.0 1.0"/>
      </material>
      <origin rpy="0 0 0" xyz="0 0 0"/>
    </visual>
    <!--物理的特性-->
    <!--干渉-->
    <collision>
      <geometry>
        <mesh filename="package://snake/mesh/dynamixel.stl"/>
      </geometry>
    </collision>
    <!--慣性-->
    <inertial>
      <mass value="0.023967239474"/>
      <inertia ixx="3.5392036062e-06" ixy="0" ixz="0" iyy="3.2067700889e-06" iyz="0" izz="2.5171567719e-06"/>
    </inertial>
  </link>
  <!-- link名 -->
  <link name="dynamixel_104">
    <!-- 見た目 -->
    <visual>
      <geometry>
        <mesh filename="package://snake/mesh/dynamixel.stl"/>
      </geometry>
      <material name="red">
        <color rgba="0.7 0.0 0.0 1.0"/>
      </material>
      <origin rpy="0 0 0" xyz="0 0 0"/>
    </visual>
    <!--物理的特性-->
    <!--干渉-->
    <collision>
      <geometry>
        <mesh filename="package://snake/mesh/dynamixel.stl"/>
      </geometry>
    </collision>
    <!--慣性-->
    <inertial>
      <mass value="0.023967239474"/>
      <inertia ixx="3.5392036062e-06" ixy="0" ixz="0" iyy="3.2067700889e-06" iyz="0" izz="2.5171567719e-06"/>
    </inertial>
  </link>
  <!-- link名 -->
  <link name="dynamixel_005">
    <!-- 見た目 -->
    <visual>
      <geometry>
        <mesh filename="package://snake/mesh/dynamixel.stl"/>
      </geometry>
      <material name="red">
        <color rgba="0.7 0.0 0.0 1.0"/>
      </material>
      <origin rpy="0 0 0" xyz="0 0 0"/>
    </visual>
    <!--物理的特性-->
    <!--干渉-->
    <collision>
      <geometry>
        <mesh filename="package://snake/mesh/dynamixel.stl"/>
      </geometry>
    </collision>
    <!--慣性-->
    <inertial>
      <mass value="0.023967239474"/>
      <inertia ixx="3.5392036062e-06" ixy="0" ixz="0" iyy="3.2067700889e-06" iyz="0" izz="2.5171567719e-06"/>
    </inertial>
  </link>
  <!-- link名 -->
  <link name="dynamixel_105">
    <!-- 見た目 -->
    <visual>
      <geometry>
        <mesh filename="package://snake/mesh/dynamixel.stl"/>
      </geometry>
      <material name="red">
        <color rgba="0.7 0.0 0.0 1.0"/>
      </material>
      <origin rpy="0 0 0" xyz="0 0 0"/>
    </visual>
    <!--物理的特性-->
    <!--干渉-->
    <collision>
      <geometry>
        <mesh filename="package://snake/mesh/dynamixel.stl"/>
      </geometry>
    </collision>
    <!--慣性-->
    <inertial>
      <mass value="0.023967239474"/>
      <inertia ixx="3.5392036062e-06" ixy="0" ixz="0" iyy="3.2067700889e-06" iyz="0" izz="2.5171567719e-06"/>
    </inertial>
  </link>
  <link name="bracket_001">
    <visual>
      <geometry>
        <mesh filename="package://snake/mesh/adaptor.stl"/>
      </geometry>
      <material name="silver">
        <color rgba="0.75 0.75 0.75 1"/>
      </material>
      <origin rpy="0 0 0" xyz="0 0 0"/>
    </visual>
    <!--物理的特性-->
    <!--干渉-->
    <collision>
      <geometry>
        <mesh filename="package://snake/mesh/adaptor.stl"/>
      </geometry>
    </collision>
    <!--慣性-->
    <inertial>
      <mass value="0.0060293114415"/>
      <inertia ixx="1.4057440439e-06" ixy="0" ixz="0" iyy="1.144769055e-06" iyz="0" izz="5.779531603e-07"/>
    </inertial>
  </link>
  <link name="bracket_002">
    <visual>
      <geometry>
        <mesh filename="package://snake/mesh/adaptor.stl"/>
      </geometry>
      <material name="silver">
        <color rgba="0.75 0.75 0.75 1"/>
      </material>
      <origin rpy="0 0 0" xyz="0 0 0"/>
    </visual>
    <!--物理的特性-->
    <!--干渉-->
    <collision>
      <geometry>
        <mesh filename="package://snake/mesh/adaptor.stl"/>
      </geometry>
    </collision>
    <!--慣性-->
    <inertial>
      <mass value="0.0060293114415"/>
      <inertia ixx="1.4057440439e-06" ixy="0" ixz="0" iyy="1.144769055e-06" iyz="0" izz="5.779531603e-07"/>
    </inertial>
  </link>
  <link name="bracket_003">
    <visual>
      <geometry>
        <mesh filename="package://snake/mesh/adaptor.stl"/>
      </geometry>
      <material name="silver">
        <color rgba="0.75 0.75 0.75 1"/>
      </material>
      <origin rpy="0 0 0" xyz="0 0 0"/>
    </visual>
    <!--物理的特性-->
    <!--干渉-->
    <collision>
      <geometry>
        <mesh filename="package://snake/mesh/adaptor.stl"/>
      </geometry>
    </collision>
    <!--慣性-->
    <inertial>
      <mass value="0.0060293114415"/>
      <inertia ixx="1.4057440439e-06" ixy="0" ixz="0" iyy="1.144769055e-06" iyz="0" izz="5.779531603e-07"/>
    </inertial>
  </link>
  <link name="bracket_004">
    <visual>
      <geometry>
        <mesh filename="package://snake/mesh/adaptor.stl"/>
      </geometry>
      <material name="silver">
        <color rgba="0.75 0.75 0.75 1"/>
      </material>
      <origin rpy="0 0 0" xyz="0 0 0"/>
    </visual>
    <!--物理的特性-->
    <!--干渉-->
    <collision>
      <geometry>
        <mesh filename="package://snake/mesh/adaptor.stl"/>
      </geometry>
    </collision>
    <!--慣性-->
    <inertial>
      <mass value="0.0060293114415"/>
      <inertia ixx="1.4057440439e-06" ixy="0" ixz="0" iyy="1.144769055e-06" iyz="0" izz="5.779531603e-07"/>
    </inertial>
  </link>
  <link name="bracket_005">
    <visual>
      <geometry>
        <mesh filename="package://snake/mesh/adaptor.stl"/>
      </geometry>
      <material name="silver">
        <color rgba="0.75 0.75 0.75 1"/>
      </material>
      <origin rpy="0 0 0" xyz="0 0 0"/>
    </visual>
    <!--物理的特性-->
    <!--干渉-->
    <collision>
      <geometry>
        <mesh filename="package://snake/mesh/adaptor.stl"/>
      </geometry>
    </collision>
    <!--慣性-->
    <inertial>
      <mass value="0.0060293114415"/>
      <inertia ixx="1.4057440439e-06" ixy="0" ixz="0" iyy="1.144769055e-06" iyz="0" izz="5.779531603e-07"/>
    </inertial>
  </link>
  <link name="bracket_006">
    <visual>
      <geometry>
        <mesh filename="package://snake/mesh/adaptor.stl"/>
      </geometry>
      <material name="silver">
        <color rgba="0.75 0.75 0.75 1"/>
      </material>
      <origin rpy="0 0 0" xyz="0 0 0"/>
    </visual>
    <!--物理的特性-->
    <!--干渉-->
    <collision>
      <geometry>
        <mesh filename="package://snake/mesh/adaptor.stl"/>
      </geometry>
    </collision>
    <!--慣性-->
    <inertial>
      <mass value="0.0060293114415"/>
      <inertia ixx="1.4057440439e-06" ixy="0" ixz="0" iyy="1.144769055e-06" iyz="0" izz="5.779531603e-07"/>
    </inertial>
  </link>
  <link name="bracket_007">
    <visual>
      <geometry>
        <mesh filename="package://snake/mesh/adaptor.stl"/>
      </geometry>
      <material name="silver">
        <color rgba="0.75 0.75 0.75 1"/>
      </material>
      <origin rpy="0 0 0" xyz="0 0 0"/>
    </visual>
    <!--物理的特性-->
    <!--干渉-->
    <collision>
      <geometry>
        <mesh filename="package://snake/mesh/adaptor.stl"/>
      </geometry>
    </collision>
    <!--慣性-->
    <inertial>
      <mass value="0.0060293114415"/>
      <inertia ixx="1.4057440439e-06" ixy="0" ixz="0" iyy="1.144769055e-06" iyz="0" izz="5.779531603e-07"/>
    </inertial>
  </link>
  <link name="bracket_008">
    <visual>
      <geometry>
        <mesh filename="package://snake/mesh/adaptor.stl"/>
      </geometry>
      <material name="silver">
        <color rgba="0.75 0.75 0.75 1"/>
      </material>
      <origin rpy="0 0 0" xyz="0 0 0"/>
    </visual>
    <!--物理的特性-->
    <!--干渉-->
    <collision>
      <geometry>
        <mesh filename="package://snake/mesh/adaptor.stl"/>
      </geometry>
    </collision>
    <!--慣性-->
    <inertial>
      <mass value="0.0060293114415"/>
      <inertia ixx="1.4057440439e-06" ixy="0" ixz="0" iyy="1.144769055e-06" iyz="0" izz="5.779531603e-07"/>
    </inertial>
  </link>
  <link name="bracket_009">
    <visual>
      <geometry>
        <mesh filename="package://snake/mesh/adaptor.stl"/>
      </geometry>
      <material name="silver">
        <color rgba="0.75 0.75 0.75 1"/>
      </material>
      <origin rpy="0 0 0" xyz="0 0 0"/>
    </visual>
    <!--物理的特性-->
    <!--干渉-->
    <collision>
      <geometry>
        <mesh filename="package://snake/mesh/adaptor.stl"/>
      </geometry>
    </collision>
    <!--慣性-->
    <inertial>
      <mass value="0.0060293114415"/>
      <inertia ixx="1.4057440439e-06" ixy="0" ixz="0" iyy="1.144769055e-06" iyz="0" izz="5.779531603e-07"/>
    </inertial>
  </link>
  <link name="bracket_010">
    <visual>
      <geometry>
        <mesh filename="package://snake/mesh/adaptor.stl"/>
      </geometry>
      <material name="silver">
        <color rgba="0.75 0.75 0.75 1"/>
      </material>
      <origin rpy="0 0 0" xyz="0 0 0"/>
    </visual>
    <!--物理的特性-->
    <!--干渉-->
    <collision>
      <geometry>
        <mesh filename="package://snake/mesh/adaptor.stl"/>
      </geometry>
    </collision>
    <!--慣性-->
    <inertial>
      <mass value="0.0060293114415"/>
      <inertia ixx="1.4057440439e-06" ixy="0" ixz="0" iyy="1.144769055e-06" iyz="0" izz="5.779531603e-07"/>
    </inertial>
  </link>
  <!--ジョイントの定義-->
  <!--ワールドとリンク1-->
  <joint name="fixed_000" type="fixed">
    <parent link="world"/>
    <child link="dynamixel_001"/>
    <origin rpy="0 0 -1.57079632679" xyz="0 0 0"/>
    <limit effort="0" lower="-1.57079632679" upper="1.57079632679" velocity="0"/>
  </joint>
  <joint name="joint_001" type="revolute">
    <axis xyz="0 1 0"/>
    <parent link="dynamixel_001"/>
    <child link="bracket_001"/>
    <origin rpy="0 0 0" xyz="0 0 0"/>
    <limit effort="0" lower="-1.57079632679" upper="1.57079632679" velocity="0"/>
  </joint>
  <joint name="fixed_001" type="fixed">
    <parent link="bracket_001"/>
    <child link="dynamixel_101"/>
    <origin rpy="1.57079632679 0 0" xyz="0.046 0 0"/>
    <limit effort="0" lower="-1.57079632679" upper="1.57079632679" velocity="0"/>
  </joint>
  <joint name="joint_002" type="revolute">
    <axis xyz="0 1 0"/>
    <parent link="dynamixel_101"/>
    <child link="bracket_002"/>
    <origin rpy="0 0 0" xyz="0 0 0"/>
    <limit effort="0" lower="-1.57079632679" upper="1.57079632679" velocity="0"/>
  </joint>
  <joint name="fixed_002" type="fixed">
    <parent link="bracket_002"/>
    <child link="dynamixel_002"/>
    <origin rpy="-1.57079632679 0 0" xyz="0.046 0 0"/>
    <limit effort="0" lower="-1.57079632679" upper="1.57079632679" velocity="0"/>
  </joint>
  <joint name="joint_003" type="revolute">
    <axis xyz="0 1 0"/>
    <parent link="dynamixel_002"/>
    <child link="bracket_003"/>
    <origin rpy="0 0 0" xyz="0 0 0"/>
    <limit effort="0" lower="-1.57079632679" upper="1.57079632679" velocity="0"/>
  </joint>
  <joint name="fixed_003" type="fixed">
    <parent link="bracket_003"/>
    <child link="dynamixel_102"/>
    <origin rpy="1.57079632679 0 0" xyz="0.046 0 0"/>
    <limit effort="0" lower="-1.57079632679" upper="1.57079632679" velocity="0"/>
  </joint>
  <joint name="joint_004" type="revolute">
    <axis xyz="0 1 0"/>
    <parent link="dynamixel_102"/>
    <child link="bracket_004"/>
    <origin rpy="0 0 0" xyz="0 0 0"/>
    <limit effort="0" lower="-1.57079632679" upper="1.57079632679" velocity="0"/>
  </joint>
  <joint name="fixed_004" type="fixed">
    <parent link="bracket_004"/>
    <child link="dynamixel_003"/>
    <origin rpy="-1.57079632679 0 0" xyz="0.046 0 0"/>
    <limit effort="0" lower="-1.57079632679" upper="1.57079632679" velocity="0"/>
  </joint>
  <joint name="joint_005" type="revolute">
    <axis xyz="0 1 0"/>
    <parent link="dynamixel_003"/>
    <child link="bracket_005"/>
    <origin rpy="0 0 0" xyz="0 0 0"/>
    <limit effort="0" lower="-1.57079632679" upper="1.57079632679" velocity="0"/>
  </joint>
  <joint name="fixed_005" type="fixed">
    <parent link="bracket_005"/>
    <child link="dynamixel_103"/>
    <origin rpy="1.57079632679 0 0" xyz="0.046 0 0"/>
    <limit effort="0" lower="-1.57079632679" upper="1.57079632679" velocity="0"/>
  </joint>
  <joint name="joint_006" type="revolute">
    <axis xyz="0 1 0"/>
    <parent link="dynamixel_103"/>
    <child link="bracket_006"/>
    <origin rpy="0 0 0" xyz="0 0 0"/>
    <limit effort="0" lower="-1.57079632679" upper="1.57079632679" velocity="0"/>
  </joint>
  <joint name="fixed_006" type="fixed">
    <parent link="bracket_006"/>
    <child link="dynamixel_004"/>
    <origin rpy="-1.57079632679 0 0" xyz="0.046 0 0"/>
    <limit effort="0" lower="-1.57079632679" upper="1.57079632679" velocity="0"/>
  </joint>
  <joint name="joint_007" type="revolute">
    <axis xyz="0 1 0"/>
    <parent link="dynamixel_004"/>
    <child link="bracket_007"/>
    <origin rpy="0 0 0" xyz="0 0 0"/>
    <limit effort="0" lower="-1.57079632679" upper="1.57079632679" velocity="0"/>
  </joint>
  <joint name="fixed_007" type="fixed">
    <parent link="bracket_007"/>
    <child link="dynamixel_104"/>
    <origin rpy="1.57079632679 0 0" xyz="0.046 0 0"/>
    <limit effort="0" lower="-1.57079632679" upper="1.57079632679" velocity="0"/>
  </joint>
  <joint name="joint_008" type="revolute">
    <axis xyz="0 1 0"/>
    <parent link="dynamixel_104"/>
    <child link="bracket_008"/>
    <origin rpy="0 0 0" xyz="0 0 0"/>
    <limit effort="0" lower="-1.57079632679" upper="1.57079632679" velocity="0"/>
  </joint>
  <joint name="fixed_008" type="fixed">
    <parent link="bracket_008"/>
    <child link="dynamixel_005"/>
    <origin rpy="-1.57079632679 0 0" xyz="0.046 0 0"/>
    <limit effort="0" lower="-1.57079632679" upper="1.57079632679" velocity="0"/>
  </joint>
  <joint name="joint_009" type="revolute">
    <axis xyz="0 1 0"/>
    <parent link="dynamixel_005"/>
    <child link="bracket_009"/>
    <origin rpy="0 0 0" xyz="0 0 0"/>
    <limit effort="0" lower="-1.57079632679" upper="1.57079632679" velocity="0"/>
  </joint>
  <joint name="fixed_009" type="fixed">
    <parent link="bracket_009"/>
    <child link="dynamixel_105"/>
    <origin rpy="1.57079632679 0 0" xyz="0.046 0 0"/>
    <limit effort="0" lower="-1.57079632679" upper="1.57079632679" velocity="0"/>
  </joint>
  <joint name="joint_010" type="revolute">
    <axis xyz="0 1 0"/>
    <parent link="dynamixel_105"/>
    <child link="bracket_010"/>
    <origin rpy="0 0 0" xyz="0 0 0"/>
    <limit effort="0" lower="-1.57079632679" upper="1.57079632679" velocity="0"/>
  </joint>
</robot>

